# PH2091: Throw Inner Exception

| Property | Value  |
|--|--|
| Package | [Philips.CodeAnalysis.MaintainabilityAnalyzers](https://www.nuget.org/packages/Philips.CodeAnalysis.MaintainabilityAnalyzers) |
| Diagnostic ID | PH2091 |
| Category  | [Maintainability](../Maintainability.md) |
| Analyzer | [ThrowInnerExceptionAnalyzer](https://github.com/philips-software/roslyn-analyzers/blob/main/Philips.CodeAnalysis.MaintainabilityAnalyzers/Maintainability/ThrowInnerExceptionAnalyzer.cs)
| CodeFix  | No |
| Severity | Error |
| Enabled By Default | Yes |

## Introduction

When throwing an exception inside a `catch` block, include the original exception as arguments. This will show the inner exception also in a Callstack, making debugging easier.

## How to solve

When throwing an exception inside a `catch` block, either throw the original exception or include the original exception in the Exception you throw. Many exceptions have an overload of the constructor for this purpose.

## Example

Code that triggers a diagnostic:
``` cs
class BadExample
{
    public void BadMethod()
    {
        try
        {
            // Some code
        }
        catch (Exception) 
        {
            throw new ArgumentException();
        }
    }
}

```

And the replacement code:
``` cs
class GoodExample
{
    public void GoodMethod()
    {
        try
        {
            // Some code
        }
        catch (Exception ex) 
        {
            LogException(ex, "Because of ...");
            throw ex;
        }
    }
}

```

## Configuration

This analyzer does not offer any special configuration. The general ways of [suppressing](https://learn.microsoft.com/en-us/dotnet/fundamentals/code-analysis/suppress-warnings) diagnostics apply.
